<?xml version="1.0"?>
<robot xmlns:xacro="http://wiki.ros.org/xacro">
  <xacro:include filename="$(find kuka_resources)/urdf/common_constants.xacro"/>
  <xacro:include filename="$(find kuka_resources)/urdf/common_materials.xacro"/>

  <xacro:macro name="kuka_kr3r540" params="prefix">
    <link name="${prefix}base_link">
      <visual>
        <origin xyz="0 0 0" rpy="0 0 0" />
        <geometry>
          <mesh filename="package://kuka_kr3_support/meshes/kr3r540/visual/base_link.dae" />
        </geometry>
        <xacro:material_kuka_pedestal />
      </visual>
      <collision>
        <origin xyz="0 0 0" rpy="0 0 0" />
        <geometry>
          <mesh filename="package://kuka_kr3_support/meshes/kr3r540/collision/base_link.stl" />
        </geometry>
      </collision>
    </link>
    <link name="${prefix}link_1">
      <visual>
        <origin xyz="0 0 0" rpy="0 0 0" />
        <geometry>
          <mesh filename="package://kuka_kr3_support/meshes/kr3r540/visual/link_1.dae" />
        </geometry>
        <xacro:material_kuka_ral_pure_white />
      </visual>
      <collision>
        <origin xyz="0 0 0" rpy="0 0 0" />
        <geometry>
          <mesh filename="package://kuka_kr3_support/meshes/kr3r540/collision/link_1.stl" />
        </geometry>
      </collision>
    </link>
    <link name="${prefix}link_2">
      <visual>
        <origin xyz="0 0 0" rpy="0 0 0" />
        <geometry>
          <mesh filename="package://kuka_kr3_support/meshes/kr3r540/visual/link_2.dae" />
        </geometry>
        <xacro:material_kuka_ral_pure_white />
      </visual>
      <collision>
        <origin xyz="0 0 0" rpy="0 0 0" />
        <geometry>
          <mesh filename="package://kuka_kr3_support/meshes/kr3r540/collision/link_2.stl" />
        </geometry>
      </collision>
    </link>
    <link name="${prefix}link_3">
      <visual>
        <origin xyz="0 0 0" rpy="0 0 0" />
        <geometry>
          <mesh filename="package://kuka_kr3_support/meshes/kr3r540/visual/link_3.dae" />
        </geometry>
        <xacro:material_kuka_ral_pure_white />
      </visual>
      <collision>
        <origin xyz="0 0 0" rpy="0 0 0" />
        <geometry>
          <mesh filename="package://kuka_kr3_support/meshes/kr3r540/collision/link_3.stl" />
        </geometry>
      </collision>
    </link>
    <link name="${prefix}link_4">
      <visual>
        <origin xyz="0 0 0" rpy="0 0 0" />
        <geometry>
          <mesh filename="package://kuka_kr3_support/meshes/kr3r540/visual/link_4.dae" />
        </geometry>
        <xacro:material_kuka_ral_pure_white />
      </visual>
      <collision>
        <origin xyz="0 0 0" rpy="0 0 0" />
        <geometry>
          <mesh filename="package://kuka_kr3_support/meshes/kr3r540/collision/link_4.stl" />
        </geometry>
      </collision>
    </link>
    <link name="${prefix}link_5">
      <visual>
        <origin xyz="0 0 0" rpy="0 0 0" />
        <geometry>
          <mesh filename="package://kuka_kr3_support/meshes/kr3r540/visual/link_5.dae" />
        </geometry>
        <xacro:material_kuka_ral_pure_white />
      </visual>
      <collision>
        <origin xyz="0 0 0" rpy="0 0 0" />
        <geometry>
          <mesh filename="package://kuka_kr3_support/meshes/kr3r540/collision/link_5.stl" />
        </geometry>
      </collision>
    </link>
    <link name="${prefix}link_6">
      <visual>
        <origin xyz="0 0 0" rpy="0 0 0" />
        <geometry>
          <mesh filename="package://kuka_kr3_support/meshes/kr3r540/visual/link_6.dae" />
        </geometry>
        <xacro:material_kuka_pedestal />
      </visual>
      <collision>
        <origin xyz="0 0 0" rpy="0 0 0" />
        <geometry>
          <mesh filename="package://kuka_kr3_support/meshes/kr3r540/collision/link_6.stl" />
        </geometry>
      </collision>
    </link>
    <!-- This frame corresponds to the $FLANGE coordinate system in KUKA KRC controllers. -->
    <link name="${prefix}tool0" />

    <joint name="${prefix}joint_a1" type="revolute">
      <origin xyz="0 0 0.345" rpy="0 0 0"/>
      <parent link="${prefix}base_link"/>
      <child link="${prefix}link_1"/>
      <axis xyz="0 0 -1"/>
      <limit lower="${-170 * DEG2RAD}" upper="${170 * DEG2RAD}" effort="0" velocity="${530 * DEG2RAD}"/>
    </joint>
    <joint name="${prefix}joint_a2" type="revolute">
      <origin xyz="0.020 0 0" rpy="0 0 0"/>
      <parent link="${prefix}link_1"/>
      <child link="${prefix}link_2"/>
      <axis xyz="0 1 0"/>
      <limit lower="${-170 * DEG2RAD}" upper="${50 * DEG2RAD}" effort="0" velocity="${529 * DEG2RAD}"/>
    </joint>
    <joint name="${prefix}joint_a3" type="revolute">
      <origin xyz="0.260 0 0" rpy="0 0 0"/>
      <parent link="${prefix}link_2"/>
      <child link="${prefix}link_3"/>
      <axis xyz="0 1 0"/>
      <limit lower="${-110 * DEG2RAD}" upper="${155 * DEG2RAD}" effort="0" velocity="${538 * DEG2RAD}"/>
    </joint>
    <joint name="${prefix}joint_a4" type="revolute">
      <origin xyz="0 0 0.020" rpy="0 0 0"/>
      <parent link="${prefix}link_3"/>
      <child link="${prefix}link_4"/>
      <axis xyz="-1 0 0"/>
      <limit lower="${-175 * DEG2RAD}" upper="${175 * DEG2RAD}" effort="0" velocity="${600 * DEG2RAD}"/>
    </joint>
    <joint name="${prefix}joint_a5" type="revolute">
      <origin xyz="0.260 0 0" rpy="0 0 0"/>
      <parent link="${prefix}link_4"/>
      <child link="${prefix}link_5"/>
      <axis xyz="0 1 0"/>
      <limit lower="${-120 * DEG2RAD}" upper="${120 * DEG2RAD}" effort="0" velocity="${600 * DEG2RAD}"/>
    </joint>
    <joint name="${prefix}joint_a6" type="revolute">
      <origin xyz="0.075 0 0" rpy="0 0 0"/>
      <parent link="${prefix}link_5"/>
      <child link="${prefix}link_6"/>
      <axis xyz="-1 0 0"/>
      <limit lower="${-350 * DEG2RAD}" upper="${350 * DEG2RAD}" effort="0" velocity="${800 * DEG2RAD}"/>
    </joint>
    <joint name="${prefix}joint_a6-tool0" type="fixed">
      <parent link="${prefix}link_6"/>
      <child link="${prefix}tool0"/>
      <origin xyz="0 0 0" rpy="0 ${90 * DEG2RAD} 0"/>
    </joint>

    <!-- ROS base_link to KUKA $ROBROOT coordinate system transform -->
    <link name="${prefix}base" />
    <joint name="${prefix}base_link-base" type="fixed">
      <origin xyz="0 0 0" rpy="0 0 0"/>
      <parent link="${prefix}base_link"/>
      <child link="${prefix}base"/>
    </joint>
  </xacro:macro>
</robot>
