<?xml version="1.0" ?>
<!-- =================================================================================== -->
<!-- |    This document was autogenerated by xacro from kr10r1100sixx.xacro            | -->
<!-- |    EDITING THIS FILE BY HAND IS NOT RECOMMENDED                                 | -->
<!-- =================================================================================== -->
<robot name="kuka_kr10r1100sixx">
  <!-- colours based on RAL values given in "FAQ - Colours of robot and robot
       controller", version "KUKA.Tifs | 2010-01-21 |YM| DefaultColorsRobotAndController.doc",
       downloaded 2015-07-18 from
       http://www.kuka.be/main/cservice/faqs/hardware/DefaultColorsRobotAndController.pdf

       all RAL colours converted using http://www.visual-graphics.de/en/customer-care/ral-colours
  -->
  <link name="base_link">
    <visual>
      <origin rpy="0 0 0" xyz="0 0 0"/>
      <geometry>
        <mesh filename="package://kuka_kr10_support/meshes/kr10r1100sixx/visual/base_link.stl"/>
      </geometry>
      <material name="">
        <color rgba="0.054901960784313725 0.054901960784313725 0.06274509803921569 1.0"/>
      </material>
    </visual>
    <collision>
      <origin rpy="0 0 0" xyz="0 0 0"/>
      <geometry>
        <mesh filename="package://kuka_kr10_support/meshes/kr10r1100sixx/collision/base_link.stl"/>
      </geometry>
    </collision>
    <inertial>
      <!--mass value="14" /-->
      <!--origin xyz="-0.0444859 -4.97e-05 0.1100921" rpy="0 0 0" /-->
      <!--inertia ixx="0.08877213773" ixy="-0.000131033070251" ixz="-0.00150261923247" iyy="0.14293778144" iyz="-2.25256850538e-05" izz="0.126259385464" /-->
      <origin rpy="0 0 0" xyz="0 0 0"/>
      <mass value="10000.0"/>
      <inertia ixx="10000.0" ixy="0" ixz="0" iyy="10000.0" iyz="0" izz="10000.0"/>
    </inertial>
  </link>
  <link name="link_1">
    <visual>
      <origin rpy="0 0 0" xyz="0 0 0"/>
      <geometry>
        <mesh filename="package://kuka_kr10_support/meshes/kr10r1100sixx/visual/link_1.stl"/>
      </geometry>
      <material name="">
        <color rgba="0.9647058823529412 0.47058823529411764 0.1568627450980392 1.0"/>
      </material>
    </visual>
    <collision>
      <origin rpy="0 0 0" xyz="0 0 0"/>
      <geometry>
        <mesh filename="package://kuka_kr10_support/meshes/kr10r1100sixx/collision/link_1.stl"/>
      </geometry>
    </collision>
    <inertial>
      <mass value="11.2"/>
      <origin rpy="0 0 0" xyz="0.0146723 5.46e-05 -0.0557645"/>
      <inertia ixx="0.10800091083" ixy="0.000256908100066" ixz="-0.00448959204754" iyy="0.0892932854513" iyz="-0.000186133409604" izz="0.0838171097348"/>
    </inertial>
  </link>
  <link name="link_2">
    <visual>
      <origin rpy="0 0 0" xyz="0 0 0"/>
      <geometry>
        <mesh filename="package://kuka_kr10_support/meshes/kr10r1100sixx/visual/link_2.stl"/>
      </geometry>
      <material name="">
        <color rgba="0.9647058823529412 0.47058823529411764 0.1568627450980392 1.0"/>
      </material>
    </visual>
    <collision>
      <origin rpy="0 0 0" xyz="0 0 0"/>
      <geometry>
        <mesh filename="package://kuka_kr10_support/meshes/kr10r1100sixx/collision/link_2.stl"/>
      </geometry>
    </collision>
    <inertial>
      <mass value="8.4"/>
      <origin rpy="0 0 0" xyz="0.2482357 -0.0029221 0.0079418"/>
      <inertia ixx="0.0365241429014" ixy="0.00223732223794" ixz="-0.00177293915942" iyy="0.378539351981" iyz="2.8964263294e-06" izz="0.392538210121"/>
    </inertial>
  </link>
  <link name="link_3">
    <visual>
      <origin rpy="0 0 0" xyz="0 0 0"/>
      <geometry>
        <mesh filename="package://kuka_kr10_support/meshes/kr10r1100sixx/visual/link_3.stl"/>
      </geometry>
      <material name="">
        <color rgba="0.9647058823529412 0.47058823529411764 0.1568627450980392 1.0"/>
      </material>
    </visual>
    <collision>
      <origin rpy="0 0 0" xyz="0 0 0"/>
      <geometry>
        <mesh filename="package://kuka_kr10_support/meshes/kr10r1100sixx/collision/link_3.stl"/>
      </geometry>
    </collision>
    <inertial>
      <mass value="8.4"/>
      <origin rpy="0 0 0" xyz="0.0160924 2.38e-05 0.0105013"/>
      <inertia ixx="0.0238712171376" ixy="1.72719757663e-06" ixz="-0.00409828855491" iyy="0.0325090200419" iyz="-1.11535979101e-05" izz="0.0287380207905"/>
    </inertial>
  </link>
  <link name="link_4">
    <visual>
      <origin rpy="0 0 0" xyz="0 0 0"/>
      <geometry>
        <mesh filename="package://kuka_kr10_support/meshes/kr10r1100sixx/visual/link_4.stl"/>
      </geometry>
      <material name="">
        <color rgba="0.9647058823529412 0.47058823529411764 0.1568627450980392 1.0"/>
      </material>
    </visual>
    <collision>
      <origin rpy="0 0 0" xyz="0 0 0"/>
      <geometry>
        <mesh filename="package://kuka_kr10_support/meshes/kr10r1100sixx/collision/link_4.stl"/>
      </geometry>
    </collision>
    <inertial>
      <mass value="5.6"/>
      <origin rpy="0 0 0" xyz="0.301148 -0.0004543 0.000235"/>
      <inertia ixx="0.0101469645454" ixy="0.000122992246096" ixz="-8.45337146292e-05" iyy="0.070495864179" iyz="8.8953596453e-07" izz="0.0717697213772"/>
    </inertial>
  </link>
  <link name="link_5">
    <visual>
      <origin rpy="0 0 0" xyz="0 0 0"/>
      <geometry>
        <mesh filename="package://kuka_kr10_support/meshes/kr10r1100sixx/visual/link_5.stl"/>
      </geometry>
      <material name="">
        <color rgba="0.9647058823529412 0.47058823529411764 0.1568627450980392 1.0"/>
      </material>
    </visual>
    <collision>
      <origin rpy="0 0 0" xyz="0 0 0"/>
      <geometry>
        <mesh filename="package://kuka_kr10_support/meshes/kr10r1100sixx/collision/link_5.stl"/>
      </geometry>
    </collision>
    <inertial>
      <mass value="5.6"/>
      <origin rpy="0 0 0" xyz="0.0157906 0.0019162 -0.0002449"/>
      <inertia ixx="0.00402901710341" ixy="0.000210543968708" ixz="4.6068390983e-05" iyy="0.00668778512296" iyz="1.26910167997e-06" izz="0.00711775677213"/>
    </inertial>
  </link>
  <link name="link_6">
    <visual>
      <origin rpy="0 0 0" xyz="0 0 0"/>
      <geometry>
        <mesh filename="package://kuka_kr10_support/meshes/kr10r1100sixx/visual/link_6.stl"/>
      </geometry>
      <material name="">
        <color rgba="0.5058823529411764 0.47058823529411764 0.38823529411764707 1.0"/>
      </material>
    </visual>
    <collision>
      <origin rpy="0 0 0" xyz="0 0 0"/>
      <geometry>
        <mesh filename="package://kuka_kr10_support/meshes/kr10r1100sixx/collision/link_6.stl"/>
      </geometry>
    </collision>
    <inertial>
      <mass value="2.8"/>
      <origin rpy="0 0 0" xyz="-0.0075312 1e-07 -0.0009341"/>
      <inertia ixx="0.000603033772181" ixy="-0.0" ixz="-4.00686891815e-06" iyy="-4.00686891815e-06" iyz="-0.0" izz="0.000340583858042"/>
    </inertial>
  </link>
  <!-- This frame corresponds to the $FLANGE coordinate system in KUKA KRC controllers. -->
  <!--link name="${prefix}tool0"/-->
  <joint name="joint_a1" type="revolute">
    <origin rpy="0 0 0" xyz="0 0 0.400"/>
    <parent link="base_link"/>
    <child link="link_1"/>
    <axis xyz="0 0 -1"/>
    <limit effort="0" lower="-2.9670597283903604" upper="2.9670597283903604" velocity="6.283185307179586"/>
  </joint>
  <joint name="joint_a2" type="revolute">
    <origin rpy="0 0 0" xyz="0.025 0 0"/>
    <parent link="link_1"/>
    <child link="link_2"/>
    <axis xyz="0 1 0"/>
    <limit effort="0" lower="-3.3161255787892263" upper="0.7853981633974483" velocity="5.235987755982989"/>
  </joint>
  <joint name="joint_a3" type="revolute">
    <origin rpy="0 0 0" xyz="0.560 0 0"/>
    <parent link="link_2"/>
    <child link="link_3"/>
    <axis xyz="0 1 0"/>
    <limit effort="0" lower="-2.0943951023931953" upper="2.722713633111154" velocity="6.283185307179586"/>
  </joint>
  <joint name="joint_a4" type="revolute">
    <origin rpy="0 0 0" xyz="0 0 0.035"/>
    <parent link="link_3"/>
    <child link="link_4"/>
    <axis xyz="-1 0 0"/>
    <!--limit effort="0" lower="${-DEG2RAD * 185}" upper="${DEG2RAD * 185}" velocity="${DEG2RAD * 381}"/-->
    <limit effort="0" lower="-2.0943951023931953" upper="2.0943951023931953" velocity="6.649704450098396"/>
  </joint>
  <joint name="joint_a5" type="revolute">
    <origin rpy="0 0 0" xyz="0.515 0 0"/>
    <parent link="link_4"/>
    <child link="link_5"/>
    <axis xyz="0 1 0"/>
    <limit effort="0" lower="-2.0943951023931953" upper="2.0943951023931953" velocity="6.771877497737998"/>
  </joint>
  <joint name="joint_a6" type="revolute">
    <origin rpy="0 0 0" xyz="0.080 0 0"/>
    <parent link="link_5"/>
    <child link="link_6"/>
    <axis xyz="-1 0 0"/>
    <limit effort="0" lower="-6.1086523819801535" upper="6.1086523819801535" velocity="10.733774899765127"/>
  </joint>
  <!--joint name="${prefix}joint_a6-tool0" type="fixed">
      <parent link="${prefix}link_6"/>
      <child link="${prefix}tool0"/>
      <origin xyz="0 0 0" rpy="0 ${DEG2RAD * 90} 0"/>
    </joint-->
  <!-- ROS base_link to KUKA $ROBROOT coordinate system transform -->
  <link name="base">
    <inertial>
      <origin rpy="0 0 0" xyz="0 0 0"/>
      <mass value="10000000000.0"/>
      <inertia ixx="100000.0" ixy="100000" ixz="100000" iyy="100000.0" iyz="100000" izz="100000.0"/>
    </inertial>
  </link>
  <joint name="base_link-base" type="fixed">
    <origin rpy="0 0 0" xyz="0 0 0"/>
    <parent link="base"/>
    <child link="base_link"/>
  </joint>
  <!--xacro:include filename="$(find kuka_kr10_support)/urdf/endorse_tool_macro.xacro" /-->
  <!--xacro:endorse_tool prefix=""/-->
  <!--xacro:include filename="$(find kuka_kr10_support)/urdf/spatula_tool.xacro" /-->
  <!--xacro:spatula_tool prefix=""/-->
  <!--xacro:include filename="$(find kuka_kr10_support)/urdf/ft_sensor_macro.xacro" /-->
  <!--xacro:kuka_ft_sensor prefix=""/-->
  <!-- colours based on RAL values given in "FAQ - Colours of robot and robot
       controller", version "KUKA.Tifs | 2010-01-21 |YM| DefaultColorsRobotAndController.doc",
       downloaded 2015-07-18 from
       http://www.kuka.be/main/cservice/faqs/hardware/DefaultColorsRobotAndController.pdf

       all RAL colours converted using http://www.visual-graphics.de/en/customer-care/ral-colours
  -->
  <link name="drilling_tool_link">
    <visual>
      <origin rpy="0 0 0" xyz="0 0 0"/>
      <geometry>
        <mesh filename="package://kuka_kr10_support/meshes/kr10r1100sixx/visual/proxxon_drilling.stl" scale="0.001 0.001 0.001"/>
      </geometry>
      <material name="">
        <color rgba="0.9647058823529412 0.47058823529411764 0.1568627450980392 1.0"/>
      </material>
    </visual>
    <collision>
      <origin rpy="0 0 0" xyz="0 0 0"/>
      <geometry>
        <mesh filename="package://kuka_kr10_support/meshes/kr10r1100sixx/collision/proxxon_drilling.stl" scale="0.001 0.001 0.001"/>
      </geometry>
    </collision>
    <inertial>
      <mass value="50"/>
      <origin rpy="0 0 0" xyz="0.05 0.00 -0.00"/>
      <inertia ixx="0.00402901710341" ixy="0.000210543968708" ixz="4.6068390983e-05" iyy="0.00668778512296" iyz="1.26910167997e-06" izz="0.00711775677213"/>
    </inertial>
  </link>
  <!-- joint between arm_6_link and drilling_tool_link -->
  <joint name="joint_drilling_tool_link" type="fixed">
    <origin rpy="0.0 0.0 1.5707963267948966" xyz="0.0375 0 0"/>
    <parent link="link_6"/>
    <child link="drilling_tool_link"/>
    <axis xyz="1 0 0"/>
    <limit effort="0" lower="0" upper="0" velocity="0"/>
  </joint>
</robot>

