<?xml version="1.0"?>
<robot xmlns:xacro="http://wiki.ros.org/xacro">

  <xacro:macro name="kuka_kr270r2700" params="prefix">
    <xacro:include filename="$(find kuka_resources)/urdf/common_materials.xacro"/>
    <!-- links -->
    <link name="${prefix}base_link">
      <visual>
        <origin xyz="0 0 0" rpy="0 0 0"/>
        <geometry>
          <mesh filename="package://kuka_kr270_support/meshes/kr270r2700/visual/base_link.dae"/>
        </geometry>
        <xacro:material_kuka_black />
      </visual>
      <collision>
        <origin xyz="0 0 0" rpy="0 0 0"/>
        <geometry>
          <mesh filename="package://kuka_kr270_support/meshes/kr270r2700/collision/base_link.stl"/>
        </geometry>
      </collision>
    </link>
    <link name="${prefix}link_1">
      <visual>
        <origin xyz="0 0 0" rpy="0 0 0"/>
        <geometry>
          <mesh filename="package://kuka_kr270_support/meshes/kr270r2700/visual/link_1.dae"/>
        </geometry>
        <xacro:material_kuka_orange />
      </visual>
      <collision>
        <origin xyz="0 0 0" rpy="0 0 0"/>
        <geometry>
          <mesh filename="package://kuka_kr270_support/meshes/kr270r2700/collision/link_1.stl"/>
        </geometry>
      </collision>
    </link>
    <link name="${prefix}link_2">
      <visual>
        <origin xyz="0 0 0" rpy="0 0 0"/>
        <geometry>
          <mesh filename="package://kuka_kr270_support/meshes/kr270r2700/visual/link_2.dae"/>
        </geometry>
        <xacro:material_kuka_orange />
      </visual>
      <collision>
        <origin xyz="0 0 0" rpy="0 0 0"/>
        <geometry>
          <mesh filename="package://kuka_kr270_support/meshes/kr270r2700/collision/link_2.stl"/>
        </geometry>
      </collision>
    </link>
    <link name="${prefix}link_3">
      <visual>
        <origin xyz="0 0 0" rpy="0 0 0"/>
        <geometry>
          <mesh filename="package://kuka_kr270_support/meshes/kr270r2700/visual/link_3.dae"/>
        </geometry>
        <xacro:material_kuka_orange />
      </visual>
      <collision>
        <origin xyz="0 0 0" rpy="0 0 0"/>
        <geometry>
          <mesh filename="package://kuka_kr270_support/meshes/kr270r2700/collision/link_3.stl"/>
        </geometry>
      </collision>
    </link>
    <link name="${prefix}link_4">
      <visual>
        <origin xyz="0 0 0" rpy="0 0 0"/>
        <geometry>
          <mesh filename="package://kuka_kr270_support/meshes/kr270r2700/visual/link_4.dae"/>
        </geometry>
        <xacro:material_kuka_orange />
      </visual>
      <collision>
        <origin xyz="0 0 0" rpy="0 0 0"/>
        <geometry>
          <mesh filename="package://kuka_kr270_support/meshes/kr270r2700/collision/link_4.stl"/>
        </geometry>
      </collision>
    </link>
    <link name="${prefix}link_5">
      <visual>
        <origin xyz="0 0 0" rpy="0 0 0"/>
        <geometry>
          <mesh filename="package://kuka_kr270_support/meshes/kr270r2700/visual/link_5.dae"/>
        </geometry>
        <xacro:material_kuka_orange />
      </visual>
      <collision>
        <origin xyz="0 0 0" rpy="0 0 0"/>
        <geometry>
          <mesh filename="package://kuka_kr270_support/meshes/kr270r2700/collision/link_5.stl"/>
        </geometry>
      </collision>
    </link>
    <link name="${prefix}link_6">
      <visual>
        <origin xyz="0 0 0 " rpy="0 0 0"/>
        <geometry>
          <mesh filename="package://kuka_kr270_support/meshes/kr270r2700/visual/link_6.dae"/>
        </geometry>
        <xacro:material_kuka_black />
      </visual>
      <collision>
        <origin xyz="0 0 0" rpy="0 0 0"/>
        <geometry>
          <mesh filename="package://kuka_kr270_support/meshes/kr270r2700/collision/link_6.stl"/>
        </geometry>
      </collision>
    </link>

    <!-- joints -->
    <joint name="${prefix}joint_a1" type="revolute">
      <origin xyz="0 0 0.675" rpy="0 0 0"/>
      <parent link="${prefix}base_link"/>
      <child link="${prefix}link_1"/>
      <axis xyz="0 0 -1"/>
      <limit lower="${radians(-185)}" upper="${radians(185)}" effort="0" velocity="${radians(105)}"/>
    </joint>
    <joint name="${prefix}joint_a2" type="revolute">
      <origin xyz="0.350 0 0" rpy="0 0 0"/>
      <parent link="${prefix}link_1"/>
      <child link="${prefix}link_2"/>
      <axis xyz="0 1 0"/>
      <limit lower="${radians(-140)}" upper="${radians(-5)}" effort="0" velocity="${radians(101)}"/>
    </joint>
    <joint name="${prefix}joint_a3" type="revolute">
      <origin xyz="1.150 0 0" rpy="0 0 0"/>
      <parent link="${prefix}link_2"/>
      <child link="${prefix}link_3"/>
      <axis xyz="0 1 0"/>
      <limit lower="${radians(-120)}" upper="${radians(155)}" effort="0" velocity="${radians(107)}"/>
    </joint>
    <joint name="${prefix}joint_a4" type="revolute">
      <origin xyz="1.200 0 -0.041" rpy="0 0 0"/>
      <parent link="${prefix}link_3"/>
      <child link="${prefix}link_4"/>
      <axis xyz="-1 0 0"/>
      <limit lower="${radians(-350)}" upper="${radians(350)}" effort="0" velocity="${radians(122)}"/>
    </joint>
    <joint name="${prefix}joint_a5" type="revolute">
      <origin xyz="0 0 0" rpy="0 0 0"/>
      <parent link="${prefix}link_4"/>
      <child link="${prefix}link_5"/>
      <axis xyz="0 1 0"/>
      <limit lower="${radians(-122.5)}" upper="${radians(122.5)}" effort="0" velocity="${radians(113)}"/>
    </joint>
    <joint name="${prefix}joint_a6" type="revolute">
      <origin xyz="0 0 0" rpy="0 0 0"/>
      <parent link="${prefix}link_5"/>
      <child link="${prefix}link_6"/>
      <axis xyz="-1 0 0"/>
      <limit lower="${radians(-350)}" upper="${radians(350)}" effort="0" velocity="${radians(175)}"/>
    </joint>

    <!-- ROS-Industrial 'flange' frame: attachment point for EEF models -->
    <link name="${prefix}flange"/>
    <joint name="${prefix}link_6-flange" type="fixed">
      <parent link="${prefix}link_6"/>
      <child link="${prefix}flange"/>
      <origin xyz="0.240 0 0" rpy="0 0 0"/>
    </joint>

    <!-- ROS base_link to KUKA $ROBROOT coordinate system transform -->
    <link name="${prefix}base" />
    <joint name="${prefix}base_link-base" type="fixed">
      <origin xyz="0 0 0" rpy="0 0 0"/>
      <parent link="${prefix}base_link"/>
      <child link="${prefix}base"/>
    </joint>

    <!-- ROS-Industrial 'tool0' frame: all-zeros tool frame -->
    <!-- This frame corresponds to the $FLANGE coordinate system in KUKA KRC controllers. -->
    <link name="${prefix}tool0" />
    <joint name="${prefix}flange-tool0" type="fixed">
      <parent link="${prefix}flange"/>
      <child link="${prefix}tool0"/>
      <origin xyz="0 0 0" rpy="0 ${radians(90)} 0"/>
    </joint>

  </xacro:macro>
</robot>
