<?xml version="1.0"?>
<robot xmlns:xacro="http://wiki.ros.org/xacro">
  <xacro:include filename="$(find kuka_resources)/urdf/common_materials.xacro"/>
  <xacro:include filename="$(find kuka_lbr_iiwa_support)/urdf/lbr_iiwa_flanges_macro.xacro"/>

  <!-- current support for the following values: basic, pneumatic_touch -->
  <xacro:arg name="flange_type" default="basic" />
  
  <xacro:macro name="kuka_lbr_iiwa_7_r800" params="prefix">
    <!-- link list -->
    <link name="${prefix}base_link">
      <visual>
        <origin xyz="0 0 0" rpy="0 0 0" />
        <geometry>
          <mesh filename="package://kuka_lbr_iiwa_support/meshes/lbr_iiwa_7_r800/visual/base_link.stl" />
        </geometry>
	<xacro:material_kuka_ral_pearly_white />
      </visual>
      <collision>
        <origin xyz="0 0 0" rpy="0 0 0" />
        <geometry>
          <mesh filename="package://kuka_lbr_iiwa_support/meshes/lbr_iiwa_7_r800/collision/base_link.stl" />
        </geometry>
      </collision>
    </link>
    <link name="${prefix}link_1">
      <visual>
        <origin xyz="0 0 0" rpy="0 0 0" />
        <geometry>
          <mesh filename="package://kuka_lbr_iiwa_support/meshes/lbr_iiwa_7_r800/visual/link_1.stl" />
        </geometry>
	<xacro:material_kuka_ral_pearly_white />
      </visual>
      <collision>
        <origin xyz="0 0 0" rpy="0 0 0" />
        <geometry>
          <mesh filename="package://kuka_lbr_iiwa_support/meshes/lbr_iiwa_7_r800/collision/link_1.stl" />
        </geometry>
      </collision>
    </link>
    <link name="${prefix}link_2">
      <visual>
        <origin xyz="0 0 0" rpy="0 0 0" />
        <geometry>
          <mesh filename="package://kuka_lbr_iiwa_support/meshes/lbr_iiwa_7_r800/visual/link_2.stl" />
        </geometry>
	<xacro:material_kuka_ral_pearly_white />
      </visual>
      <collision>
        <origin xyz="0 0 0" rpy="0 0 0" />
        <geometry>
          <mesh filename="package://kuka_lbr_iiwa_support/meshes/lbr_iiwa_7_r800/collision/link_2.stl" />
        </geometry>
      </collision>
    </link>
    <link name="${prefix}link_3">
      <visual>
        <origin xyz="0 0 0" rpy="0 0 0" />
        <geometry>
          <mesh filename="package://kuka_lbr_iiwa_support/meshes/lbr_iiwa_7_r800/visual/link_3.stl" />
        </geometry>
	<xacro:material_kuka_ral_pearly_white />
      </visual>
      <collision>
        <origin xyz="0 0 0" rpy="0 0 0" />
        <geometry>
          <mesh filename="package://kuka_lbr_iiwa_support/meshes/lbr_iiwa_7_r800/collision/link_3.stl" />
        </geometry>
      </collision>
    </link>
    <link name="${prefix}link_4">
      <visual>
        <origin xyz="0 0 0" rpy="0 0 0" />
        <geometry>
          <mesh filename="package://kuka_lbr_iiwa_support/meshes/lbr_iiwa_7_r800/visual/link_4.stl" />
        </geometry>
	<xacro:material_kuka_ral_pearly_white />
      </visual>
      <collision>
        <origin xyz="0 0 0" rpy="0 0 0" />
        <geometry>
          <mesh filename="package://kuka_lbr_iiwa_support/meshes/lbr_iiwa_7_r800/collision/link_4.stl" />
        </geometry>
      </collision>
    </link>
    <link name="${prefix}link_5">
      <visual>
        <origin xyz="0 0 0" rpy="0 0 0" />
        <geometry>
          <mesh filename="package://kuka_lbr_iiwa_support/meshes/lbr_iiwa_7_r800/visual/link_5.stl" />
        </geometry>
	<xacro:material_kuka_ral_pearly_white />
      </visual>
      <collision>
        <origin xyz="0 0 0" rpy="0 0 0" />
        <geometry>
          <mesh filename="package://kuka_lbr_iiwa_support/meshes/lbr_iiwa_7_r800/collision/link_5.stl" />
        </geometry>
      </collision>
    </link>
    <link name="${prefix}link_6">
      <visual>
        <origin xyz="0 0 0" rpy="0 0 0" />
        <geometry>
          <mesh filename="package://kuka_lbr_iiwa_support/meshes/lbr_iiwa_7_r800/visual/link_6.stl" />
        </geometry>
	<xacro:material_kuka_ral_pearly_white />
      </visual>
      <collision>
        <origin xyz="0 0 0" rpy="0 0 0" />
        <geometry>
          <mesh filename="package://kuka_lbr_iiwa_support/meshes/lbr_iiwa_7_r800/collision/link_6.stl" />
        </geometry>

      </collision>
    </link>
    <xacro:kuka_lbr_iiwa_flange_link prefix="${prefix}" flange_type="$(arg flange_type)"/>
    <link name="${prefix}tool0" />
    <!-- end of link list -->

    <!-- joint list -->
    <joint name="${prefix}joint_a1" type="revolute">
      <origin xyz="0 0 0.34" rpy="0 0 0" />
      <parent link="${prefix}base_link" />
      <child link="${prefix}link_1" />
      <axis xyz="0 0 1" />
      <limit lower="${radians(-170)}" upper="${radians(170)}" effort="0" velocity="${radians(98)}" />
    </joint>
    <joint name="${prefix}joint_a2" type="revolute">
      <origin xyz="0 0 0" rpy="0 0 0" />
      <parent link="${prefix}link_1" />
      <child link="${prefix}link_2" />
      <axis xyz="0 1 0" />
      <limit lower="${radians(-120)}" upper="${radians(120)}" effort="0" velocity="${radians(98)}" />
    </joint>
    <joint name="${prefix}joint_a3" type="revolute">
      <origin xyz="0 0 0.40" rpy="0 0 0" />
      <parent link="${prefix}link_2" />
      <child link="${prefix}link_3" />
      <axis xyz="0 0 1" />
      <limit lower="${radians(-170)}" upper="${radians(170)}" effort="0" velocity="${radians(100)}" />
    </joint>
    <joint name="${prefix}joint_a4" type="revolute">
      <origin xyz="0 0 0" rpy="0 0 0" />
      <parent link="${prefix}link_3" />
      <child link="${prefix}link_4" />
      <axis xyz="0 -1 0" />
      <limit lower="${radians(-120)}" upper="${radians(120)}" effort="0" velocity="${radians(130)}" />
    </joint>
    <joint name="${prefix}joint_a5" type="revolute">
      <origin xyz="0 0 0.40" rpy="0 0 0" />
      <parent link="${prefix}link_4" />
      <child link="${prefix}link_5" />
      <axis xyz="0 0 1" />
      <limit lower="${radians(-170)}" upper="${radians(170)}" effort="0" velocity="${radians(140)}" />
    </joint>
    <joint name="${prefix}joint_a6" type="revolute">
      <origin xyz="0 0 0" rpy="0 0 0" />
      <parent link="${prefix}link_5" />
      <child link="${prefix}link_6" />
      <axis xyz="0 1 0" />
      <limit lower="${radians(-120)}" upper="${radians(120)}" effort="0" velocity="${radians(180)}" />
    </joint>
    <xacro:kuka_lbr_iiwa_flange_joint prefix="${prefix}" flange_type="$(arg flange_type)"/>
    <joint name="${prefix}joint_a7-tool0" type="fixed">
      <origin xyz="0 0 0" rpy="0 0 0" />
      <parent link="${prefix}link_7" />
      <child link="${prefix}tool0" />
      <axis xyz="0 0 0" />
    </joint>
    <!-- end of joint list -->

    <!-- ROS base_link to KUKA $ROBROOT coordinate system transform -->
    <link name="${prefix}base" />
    <joint name="${prefix}base_link-base" type="fixed">
      <origin xyz="0 0 0" rpy="0 0 0"/>
      <parent link="${prefix}base_link"/>
      <child link="${prefix}base"/>
    </joint>
  </xacro:macro>
</robot>

