<?xml version="1.0"?>
<robot xmlns:xacro="http://wiki.ros.org/xacro">
  <xacro:macro name="kuka_kr210l150_a3" params="prefix variant">
    <joint name="${prefix}joint_a3" type="revolute">
      <xacro:if value="${variant == ''}">
	<origin xyz="0 0 1.25" rpy="0 ${radians(90)} 0"/>
      </xacro:if>
      <xacro:if value="${variant == '_2'}">
	<origin xyz="0 0 1.25" rpy="0 0 0"/>
      </xacro:if>
      <parent link="${prefix}link_2"/>
      <child link="${prefix}link_3"/>
      <axis xyz="0 1 0"/>
      <xacro:if value="${variant == ''}">
	<limit lower="${radians(-209)}" upper="${radians(65)}" effort="0" velocity="${radians(81)}"/>
      </xacro:if>
      <xacro:if value="${variant == '_2'}">
	<limit lower="${radians(-119)}" upper="${radians(155)}" effort="0" velocity="${radians(81)}"/>
      </xacro:if>
    </joint>
  </xacro:macro>
</robot>
