<?xml version="1.0"?>
<robot xmlns:xacro="http://wiki.ros.org/xacro">
  <xacro:include filename="$(find kuka_resources)/urdf/common_materials.xacro"/>

  <!-- for the KR210 L150, use ""; for the KR210 L150-2, use "_2" -->
  <xacro:arg name="variant" default="" />
  <xacro:property name="variant" value="$(arg variant)"/>
  
  <xacro:macro name="kuka_kr210l150" params="prefix">
    <!-- links -->
    <link name="${prefix}base_link">
      <visual>
        <origin xyz="0 0 0" rpy="0 0 0"/>
        <geometry>
          <mesh filename="package://kuka_kr210_support/meshes/kr210l150/visual/base_link.stl"/>
        </geometry>
	<xacro:material_kuka_pedestal />
      </visual>
      <collision>
        <origin xyz="0 0 0" rpy="0 0 0"/>
        <geometry>
          <mesh filename="package://kuka_kr210_support/meshes/kr210l150/collision/base_link.stl"/>
        </geometry>
      </collision>
    </link>
    <link name="${prefix}link_1">
      <visual>
        <origin xyz="0 0 0" rpy="0 0 0"/>
        <geometry>
          <mesh filename="package://kuka_kr210_support/meshes/kr210l150/visual/link_1.stl"/>
        </geometry>
	<xacro:material_kuka_orange />
      </visual>
      <collision>
        <origin xyz="0 0 0" rpy="0 0 0"/>
        <geometry>
          <mesh filename="package://kuka_kr210_support/meshes/kr210l150/collision/link_1.stl"/>
        </geometry>
      </collision>
    </link>
    <link name="${prefix}link_2">
      <visual>
        <origin xyz="0 0 0" rpy="0 0 0"/>
        <geometry>
          <mesh filename="package://kuka_kr210_support/meshes/kr210l150/visual/link_2.stl"/>
        </geometry>
	<xacro:material_kuka_orange />
      </visual>
      <collision>
        <origin xyz="0 0 0" rpy="0 0 0"/>
        <geometry>
          <mesh filename="package://kuka_kr210_support/meshes/kr210l150/collision/link_2.stl"/>
        </geometry>
      </collision>
    </link>
    <link name="${prefix}link_3">
      <visual>
        <origin xyz="0 0 0" rpy="0 0 0"/>
        <geometry>
          <mesh filename="package://kuka_kr210_support/meshes/kr210l150/visual/link_3.stl"/>
        </geometry>
	<xacro:material_kuka_orange />
      </visual>
      <collision>
        <origin xyz="0 0 0" rpy="0 0 0"/>
        <geometry>
          <mesh filename="package://kuka_kr210_support/meshes/kr210l150/collision/link_3.stl"/>
        </geometry>
      </collision>
    </link>
    <link name="${prefix}link_4">
      <visual>
        <origin xyz="0 0 0" rpy="0 0 0"/>
        <geometry>
          <mesh filename="package://kuka_kr210_support/meshes/kr210l150/visual/link_4.stl"/>
        </geometry>
	<xacro:material_kuka_orange />
      </visual>
      <collision>
        <origin xyz="0 0 0" rpy="0 0 0"/>
        <geometry>
          <mesh filename="package://kuka_kr210_support/meshes/kr210l150/collision/link_4.stl"/>
        </geometry>
      </collision>
    </link>
    <link name="${prefix}link_5">
      <visual>
        <origin xyz="0 0 0" rpy="0 0 0"/>
        <geometry>
          <mesh filename="package://kuka_kr210_support/meshes/kr210l150/visual/link_5.stl"/>
        </geometry>
	<xacro:material_kuka_orange />
      </visual>
      <collision>
        <origin xyz="0 0 0" rpy="0 0 0"/>
        <geometry>
          <mesh filename="package://kuka_kr210_support/meshes/kr210l150/collision/link_5.stl"/>
        </geometry>
      </collision>
    </link>
    <link name="${prefix}link_6">
      <visual>
        <origin xyz="0 0 0" rpy="0 0 0"/>
        <geometry>
          <mesh filename="package://kuka_kr210_support/meshes/kr210l150/visual/link_6.stl"/>
        </geometry>
	<xacro:material_kuka_ral_silver_gray />
      </visual>
      <collision>
        <origin xyz="0 0 0" rpy="0 0 0"/>
        <geometry>
          <mesh filename="package://kuka_kr210_support/meshes/kr210l150/collision/link_6.stl"/>
        </geometry>
      </collision>
    </link>
    <!-- This frame corresponds to the $FLANGE coordinate system in KUKA KRC controllers. -->
    <link name="${prefix}tool0"/>

    <!-- joints -->
    <joint name="${prefix}joint_a1" type="revolute">
      <origin xyz="0 0 0.75" rpy="0 0 0"/>
      <parent link="${prefix}base_link"/>
      <child link="${prefix}link_1"/>
      <axis xyz="0 0 -1"/>
      <limit lower="${radians(-185)}" upper="${radians(185)}" effort="0" velocity="${radians(86)}"/>
    </joint>
    <joint name="${prefix}joint_a2" type="revolute">
      <origin xyz="0.35 0 0" rpy="0 0 0"/>
      <parent link="${prefix}link_1"/>
      <child link="${prefix}link_2"/>
      <axis xyz="0 1 0"/>
      <limit lower="${radians(-61)}" upper="${radians(90)}" effort="0" velocity="${radians(84)}"/>
    </joint>
    <joint name="${prefix}joint_a3" type="revolute">
      <xacro:if value="${variant == ''}">
	<origin xyz="0 0 1.25" rpy="0 ${radians(90)} 0"/>
      </xacro:if>
      <xacro:if value="${variant == '_2'}">
	<origin xyz="0 0 1.25" rpy="0 0 0"/>
      </xacro:if>
      <parent link="${prefix}link_2"/>
      <child link="${prefix}link_3"/>
      <axis xyz="0 1 0"/>
      <xacro:if value="${variant == ''}">
	<limit lower="${radians(-209)}" upper="${radians(65)}" effort="0" velocity="${radians(81)}"/>
      </xacro:if>
      <xacro:if value="${variant == '_2'}">
	<limit lower="${radians(-119)}" upper="${radians(155)}" effort="0" velocity="${radians(81)}"/>
      </xacro:if>
    </joint>
    <joint name="${prefix}joint_a4" type="revolute">
      <origin xyz="0.055 0 0" rpy="0 0 0"/>
      <parent link="${prefix}link_3"/>
      <child link="${prefix}link_4"/>
      <axis xyz="0 0 1"/>
      <limit lower="${radians(-350)}" upper="${radians(350)}" effort="0" velocity="${radians(100)}"/>
    </joint>
    <joint name="${prefix}joint_a5" type="revolute">
      <origin xyz="0 0 1.5" rpy="0 0 0"/>
      <parent link="${prefix}link_4"/>
      <child link="${prefix}link_5"/>
      <axis xyz="0 1 0"/>
      <limit lower="${radians(-125)}" upper="${radians(125)}" effort="0" velocity="${radians(110)}"/>
    </joint>
    <joint name="${prefix}joint_a6" type="revolute">
      <origin xyz="0 0 0.23" rpy="0 0 0"/>
      <parent link="${prefix}link_5"/>
      <child link="${prefix}link_6"/>
      <axis xyz="0 0 1"/>
      <limit lower="${radians(-350)}" upper="${radians(350)}" effort="0" velocity="${radians(184)}"/>
    </joint>
    <joint name="${prefix}link_6-tool0" type="fixed">
      <parent link="${prefix}link_6"/>
      <child link="${prefix}tool0"/>
      <origin xyz="0 0 0" rpy="0 0 0"/>
    </joint>

    <!-- rename 'Link1' to 'link_1', maintain bw-compatibility -->
    <link name="${prefix}Link1"/>
    <joint name="${prefix}Link1-link_1" type="fixed">
      <parent link="${prefix}link_1"/>
      <child link="${prefix}Link1"/>
      <origin xyz="0 0 0" rpy="0 0 0"/>
    </joint>
  </xacro:macro>
</robot>
